export const TryCatch = (passedFunc) => async (req, res, next) => {
  try {
    await passedFunc(req, res, next);
  } catch (error) {
    next(error);
  }
};

export const errorMiddleware = (err, req, res, next) => {
  const statusCode = err.statusCode || 500;
  const message = err.message || "Internal Server Error";

  res.status(statusCode).json({
    success: false,
    message,
  });
};
